<sdf version='1.7'>
  <world name='default'>
    <light name='sun' type='directional'>
      <cast_shadows>1</cast_shadows>
      <pose>0 0 10 0 -0 0</pose>
      <diffuse>0.8 0.8 0.8 1</diffuse>
      <specular>0.2 0.2 0.2 1</specular>
      <attenuation>
        <range>1000</range>
        <constant>0.9</constant>
        <linear>0.01</linear>
        <quadratic>0.001</quadratic>
      </attenuation>
      <direction>-0.5 0.1 -0.9</direction>
      <spot>
        <inner_angle>0</inner_angle>
        <outer_angle>0</outer_angle>
        <falloff>0</falloff>
      </spot>
    </light>
    <model name='ground_plane'>
      <static>1</static>
      <link name='link'>
        <collision name='collision'>
          <geometry>
            <plane>
              <normal>0 0 1</normal>
              <size>100 100</size>
            </plane>
          </geometry>
          <surface>
            <contact>
              <collide_bitmask>65535</collide_bitmask>
              <ode/>
            </contact>
            <friction>
              <ode>
                <mu>100</mu>
                <mu2>50</mu2>
              </ode>
              <torsional>
                <ode/>
              </torsional>
            </friction>
            <bounce/>
          </surface>
          <max_contacts>10</max_contacts>
        </collision>
        <visual name='visual'>
          <cast_shadows>0</cast_shadows>
          <geometry>
            <plane>
              <normal>0 0 1</normal>
              <size>100 100</size>
            </plane>
          </geometry>
          <material>
            <script>
              <uri>file://media/materials/scripts/gazebo.material</uri>
              <name>Gazebo/Grey</name>
            </script>
          </material>
        </visual>
        <self_collide>0</self_collide>
        <enable_wind>0</enable_wind>
        <kinematic>0</kinematic>
      </link>
    </model>
    <gravity>0 0 -9.8</gravity>
    <magnetic_field>6e-06 2.3e-05 -4.2e-05</magnetic_field>
    <atmosphere type='adiabatic'/>
    <physics type='ode'>
      <max_step_size>0.001</max_step_size>
      <real_time_factor>1</real_time_factor>
      <real_time_update_rate>1000</real_time_update_rate>
    </physics>
    <scene>
      <ambient>0.4 0.4 0.4 1</ambient>
      <background>0.7 0.7 0.7 1</background>
      <shadows>1</shadows>
    </scene>
    <audio>
      <device>default</device>
    </audio>
    <wind/>
    <spherical_coordinates>
      <surface_model>EARTH_WGS84</surface_model>
      <latitude_deg>0</latitude_deg>
      <longitude_deg>0</longitude_deg>
      <elevation>0</elevation>
      <heading_deg>0</heading_deg>
    </spherical_coordinates>
    <model name='QLearn'>
      <link name='link_0'>
        <inertial>
          <mass>1</mass>
          <inertia>
            <ixx>0.166667</ixx>
            <ixy>0</ixy>
            <ixz>0</ixz>
            <iyy>0.166667</iyy>
            <iyz>0</iyz>
            <izz>0.166667</izz>
          </inertia>
          <pose>0 0 0 0 -0 0</pose>
        </inertial>
        <pose>-0 0 0 0 -0 0</pose>
        <visual name='visual'>
          <pose>0 0 0 0 -0 0</pose>
          <geometry>
            <mesh>
              <uri>file:///home/godwin/Desktop/BTP/obstacle_avoidance/src/obstacle_avoidance/world/QLearn.stl</uri>
              <scale>0.2 0.2 0.1</scale>
            </mesh>
          </geometry>
          <material>
            <lighting>1</lighting>
            <script>
              <uri>file://media/materials/scripts/gazebo.material</uri>
              <name>Gazebo/Red</name>
            </script>
            <shader type='pixel'/>
          </material>
          <transparency>0</transparency>
          <cast_shadows>1</cast_shadows>
        </visual>
        <collision name='collision'>
          <laser_retro>0</laser_retro>
          <max_contacts>10</max_contacts>
          <pose>0 0 0 0 -0 0</pose>
          <geometry>
            <mesh>
              <uri>file:///home/godwin/Desktop/BTP/obstacle_avoidance/src/obstacle_avoidance/world/QLearn.stl</uri>
              <scale>0.2 0.2 0.1</scale>
            </mesh>
          </geometry>
          <surface>
            <friction>
              <ode>
                <mu>1</mu>
                <mu2>1</mu2>
                <fdir1>0 0 0</fdir1>
                <slip1>0</slip1>
                <slip2>0</slip2>
              </ode>
              <torsional>
                <coefficient>1</coefficient>
                <patch_radius>0</patch_radius>
                <surface_radius>0</surface_radius>
                <use_patch_radius>1</use_patch_radius>
                <ode>
                  <slip>0</slip>
                </ode>
              </torsional>
            </friction>
            <bounce>
              <restitution_coefficient>0</restitution_coefficient>
              <threshold>1e+06</threshold>
            </bounce>
            <contact>
              <collide_without_contact>0</collide_without_contact>
              <collide_without_contact_bitmask>1</collide_without_contact_bitmask>
              <collide_bitmask>1</collide_bitmask>
              <ode>
                <soft_cfm>0</soft_cfm>
                <soft_erp>0.2</soft_erp>
                <kp>1e+13</kp>
                <kd>1</kd>
                <max_vel>0.01</max_vel>
                <min_depth>0</min_depth>
              </ode>
              <bullet>
                <split_impulse>1</split_impulse>
                <split_impulse_penetration_threshold>-0.01</split_impulse_penetration_threshold>
                <soft_cfm>0</soft_cfm>
                <soft_erp>0.2</soft_erp>
                <kp>1e+13</kp>
                <kd>1</kd>
              </bullet>
            </contact>
          </surface>
        </collision>
        <self_collide>0</self_collide>
        <enable_wind>0</enable_wind>
        <kinematic>0</kinematic>
      </link>
      <static>0</static>
      <allow_auto_disable>1</allow_auto_disable>
      <pose>-0.5 -1.6 0 0 -0 0</pose>
    </model>
    <state world_name='default'>
      <sim_time>1462 364000000</sim_time>
      <real_time>37 407117445</real_time>
      <wall_time>1697653786 48589229</wall_time>
      <iterations>2742</iterations>
      <model name='GD8'>
        <pose>0.000289 0.004759 0.076921 0.000164 -0.000988 0.121692</pose>
        <scale>1 1 1</scale>
        <link name='Wheel_BL_1'>
          <pose>-0.145174 0.102896 0.05081 0.000197 0.59585 0.121803</pose>
          <velocity>-3.3e-05 5e-06 0.007533 -0.00011 -0.00067 6e-06</velocity>
          <acceleration>-0.06686 0.001771 15.049 -0.344685 -0.677224 0.020442</acceleration>
          <wrench>-0.022732 0.000602 5.11665 0 -0 0</wrench>
        </link>
        <link name='Wheel_BR_1'>
          <pose>-0.117238 -0.125532 0.050771 0.000222 -0.74143 0.121543</pose>
          <velocity>-8e-06 5e-06 0.007157 -9.1e-05 -0.000152 7e-06</velocity>
          <acceleration>-0.013176 0.000333 14.3225 -0.186061 -0.564778 0.023516</acceleration>
          <wrench>-0.00448 0.000113 4.86966 0 -0 0</wrench>
        </link>
        <link name='Wheel_TL_1'>
          <pose>0.117866 0.135064 0.05107 0.000165 -0.026948 0.121688</pose>
          <velocity>4e-06 -5e-06 0.007166 9.7e-05 8.7e-05 -1.2e-05</velocity>
          <acceleration>0.010349 -0.015148 14.3424 0.275225 -0.732535 -0.014085</acceleration>
          <wrench>0.003519 -0.00515 4.87641 0 -0 0</wrench>
        </link>
        <link name='Wheel_TR_1'>
          <pose>0.145802 -0.093364 0.051034 0.000165 0.041943 0.121699</pose>
          <velocity>1e-06 -2e-06 0.007528 3.6e-05 4.9e-05 2.2e-05</velocity>
          <acceleration>0.00145 -0.009019 15.0539 0.114755 -0.366435 0.050591</acceleration>
          <wrench>0.000493 -0.003067 5.11832 0 -0 0</wrench>
        </link>
        <link name='base_link'>
          <pose>0.000289 0.004759 0.076921 0.000164 -0.000988 0.121692</pose>
          <velocity>-1.9e-05 0 0.007342 5e-06 -0.000145 0</velocity>
          <acceleration>-0.038871 -0.006056 14.6842 0.072805 -0.238847 -0.052494</acceleration>
          <wrench>-0.197137 -0.030713 74.4722 0 -0 0</wrench>
        </link>
      </model>
      <model name='QLearn'>
        <pose>1 -4 0 0 0 0</pose>
        <scale>1 1 1</scale>
        <link name='link_0'>
          <pose>0 0 0 0 0 0</pose>
          <velocity>0 0 0 0 0 0</velocity>
          <acceleration>0 0 0 0 0 0</acceleration>
          <wrench>0 0 0 0 0 0</wrench>
        </link>
      </model>
      <model name='ground_plane'>
        <pose>0 0 0 0 -0 0</pose>
        <scale>1 1 1</scale>
        <link name='link'>
          <pose>0 0 0 0 -0 0</pose>
          <velocity>0 0 0 0 -0 0</velocity>
          <acceleration>0 0 0 0 -0 0</acceleration>
          <wrench>0 0 0 0 -0 0</wrench>
        </link>
      </model>
      <light name='sun'>
        <pose>0 0 10 0 -0 0</pose>
      </light>
    </state>
    <gui fullscreen='0'>
      <camera name='user_camera'>
        <pose>-0.5 -1.6 46 0 1.5698 -0</pose>
        <view_controller>ortho</view_controller>
        <projection_type>orthographic</projection_type>
      </camera>
    </gui>
    <model name='GD8'>
      <link name='base_link'>
        <inertial>
          <pose>-0.001602 0 0.000966 0 -0 0</pose>
          <mass>5.0716</mass>
          <inertia>
            <ixx>0.0355855</ixx>
            <ixy>-0.012851</ixy>
            <ixz>0.0466213</ixz>
            <iyy>0.0756234</iyy>
            <iyz>0.080024</iyz>
            <izz>0.100939</izz>
          </inertia>
        </inertial>
        <collision name='base_link_collision'>
          <pose>0 0 0 0 -0 0</pose>
          <geometry>
            <mesh>
              <scale>0.001 0.001 0.001</scale>
              <uri>file:///home/godwin/Desktop/BTP/obstacle_avoidance/src/obstacle_avoidance/urdf/meshes/base_link.stl</uri>
            </mesh>
          </geometry>
          <surface>
            <contact>
              <ode/>
            </contact>
            <friction>
              <ode>
                <mu>0.2</mu>
                <mu2>0.2</mu2>
              </ode>
              <torsional>
                <ode/>
              </torsional>
            </friction>
            <bounce/>
          </surface>
          <max_contacts>10</max_contacts>
        </collision>
        <collision name='base_link_fixed_joint_lump__IMU_1_collision_1'>
          <pose>0 0 0 0 -0 0</pose>
          <geometry>
            <mesh>
              <scale>0.001 0.001 0.001</scale>
              <uri>file:///home/godwin/Desktop/BTP/obstacle_avoidance/src/obstacle_avoidance/urdf/meshes/IMU_1.stl</uri>
            </mesh>
          </geometry>
          <surface>
            <contact>
              <ode/>
            </contact>
            <friction>
              <ode>
                <mu>0.2</mu>
                <mu2>0.2</mu2>
              </ode>
              <torsional>
                <ode/>
              </torsional>
            </friction>
            <bounce/>
          </surface>
          <max_contacts>10</max_contacts>
        </collision>
        <collision name='base_link_fixed_joint_lump__jetson_1_collision_2'>
          <pose>0 0 0 0 -0 0</pose>
          <geometry>
            <mesh>
              <scale>0.001 0.001 0.001</scale>
              <uri>file:///home/godwin/Desktop/BTP/obstacle_avoidance/src/obstacle_avoidance/urdf/meshes/jetson_1.stl</uri>
            </mesh>
          </geometry>
          <surface>
            <contact>
              <ode/>
            </contact>
            <friction>
              <ode>
                <mu>0.2</mu>
                <mu2>0.2</mu2>
              </ode>
              <torsional>
                <ode/>
              </torsional>
            </friction>
            <bounce/>
          </surface>
          <max_contacts>10</max_contacts>
        </collision>
        <collision name='base_link_fixed_joint_lump__Lidar_v1_1_collision_3'>
          <pose>0 0 0 0 -0 0</pose>
          <geometry>
            <mesh>
              <scale>0.001 0.001 0.001</scale>
              <uri>file:///home/godwin/Desktop/BTP/obstacle_avoidance/src/obstacle_avoidance/urdf/meshes/Lidar_v1_1.stl</uri>
            </mesh>
          </geometry>
          <surface>
            <contact>
              <ode/>
            </contact>
            <friction>
              <ode>
                <mu>0.2</mu>
                <mu2>0.2</mu2>
              </ode>
              <torsional>
                <ode/>
              </torsional>
            </friction>
            <bounce/>
          </surface>
          <max_contacts>10</max_contacts>
        </collision>
        <visual name='base_link_visual'>
          <pose>0 0 0 0 -0 0</pose>
          <geometry>
            <mesh>
              <scale>0.001 0.001 0.001</scale>
              <uri>file:///home/godwin/Desktop/BTP/obstacle_avoidance/src/obstacle_avoidance/urdf/meshes/base_link.stl</uri>
            </mesh>
          </geometry>
          <material>
            <script>
              <name>Gazebo/Silver</name>
              <uri>file://media/materials/scripts/gazebo.material</uri>
            </script>
          </material>
        </visual>
        <visual name='base_link_fixed_joint_lump__IMU_1_visual_1'>
          <pose>0 0 0 0 -0 0</pose>
          <geometry>
            <mesh>
              <scale>0.001 0.001 0.001</scale>
              <uri>file:///home/godwin/Desktop/BTP/obstacle_avoidance/src/obstacle_avoidance/urdf/meshes/IMU_1.stl</uri>
            </mesh>
          </geometry>
          <material>
            <script>
              <name>Gazebo/Silver</name>
              <uri>file://media/materials/scripts/gazebo.material</uri>
            </script>
          </material>
        </visual>
        <visual name='base_link_fixed_joint_lump__jetson_1_visual_2'>
          <pose>0 0 0 0 -0 0</pose>
          <geometry>
            <mesh>
              <scale>0.001 0.001 0.001</scale>
              <uri>file:///home/godwin/Desktop/BTP/obstacle_avoidance/src/obstacle_avoidance/urdf/meshes/jetson_1.stl</uri>
            </mesh>
          </geometry>
          <material>
            <script>
              <name>Gazebo/Silver</name>
              <uri>file://media/materials/scripts/gazebo.material</uri>
            </script>
          </material>
        </visual>
        <visual name='base_link_fixed_joint_lump__Lidar_v1_1_visual_3'>
          <pose>0 0 0 0 -0 0</pose>
          <geometry>
            <mesh>
              <scale>0.001 0.001 0.001</scale>
              <uri>file:///home/godwin/Desktop/BTP/obstacle_avoidance/src/obstacle_avoidance/urdf/meshes/Lidar_v1_1.stl</uri>
            </mesh>
          </geometry>
          <material>
            <script>
              <name>Gazebo/Silver</name>
              <uri>file://media/materials/scripts/gazebo.material</uri>
            </script>
          </material>
        </visual>
        <gravity>1</gravity>
        <self_collide>1</self_collide>
        <sensor name='lidar' type='ray'>
          <always_on>1</always_on>
          <visualize>1</visualize>
          <update_rate>5</update_rate>
          <ray>
            <scan>
              <horizontal>
                <samples>360</samples>
                <resolution>1</resolution>
                <min_angle>0</min_angle>
                <max_angle>6.28</max_angle>
              </horizontal>
              <vertical>
                <samples>1</samples>
                <min_angle>0</min_angle>
                <max_angle>0</max_angle>
              </vertical>
            </scan>
            <range>
              <min>0.12</min>
              <max>1.5</max>
              <resolution>0.015</resolution>
            </range>
            <noise>
              <type>gaussian</type>
              <mean>0</mean>
              <stddev>0.01</stddev>
            </noise>
          </ray>
          <plugin name='scan' filename='libgazebo_ros_ray_sensor.so'>
            <ros>
              <remapping>~/out:=scan</remapping>
            </ros>
            <output_type>sensor_msgs/LaserScan</output_type>
            <frame_name>lidar_link</frame_name>
          </plugin>
          <pose>0 0 0.038 0 -0 0</pose>
        </sensor>
        <enable_wind>0</enable_wind>
        <kinematic>0</kinematic>
      </link>
      <joint name='Revolute 10' type='revolute'>
        <pose relative_to='base_link'>-0.1325 -0.115065 -0.026 0 -0 0</pose>
        <parent>base_link</parent>
        <child>Wheel_BR_1</child>
        <axis>
          <xyz>0 -1 0</xyz>
          <limit>
            <lower>-1e+16</lower>
            <upper>1e+16</upper>
          </limit>
          <dynamics>
            <spring_reference>0</spring_reference>
            <spring_stiffness>0</spring_stiffness>
          </dynamics>
        </axis>
      </joint>
      <link name='Wheel_BR_1'>
        <pose relative_to='Revolute 10'>0 0 0 0 -0 0</pose>
        <inertial>
          <pose>2e-06 -0.043 0 0 -0 0</pose>
          <mass>0.34</mass>
          <inertia>
            <ixx>0.001381</ixx>
            <ixy>0</ixy>
            <ixz>0</ixz>
            <iyy>0.001948</iyy>
            <iyz>0</iyz>
            <izz>0.001381</izz>
          </inertia>
        </inertial>
        <collision name='Wheel_BR_1_collision'>
          <pose>0.1325 0.115065 0.026 0 -0 0</pose>
          <geometry>
            <mesh>
              <scale>0.001 0.001 0.001</scale>
              <uri>file:///home/godwin/Desktop/BTP/obstacle_avoidance/src/obstacle_avoidance/urdf/meshes/Wheel_BR_1.stl</uri>
            </mesh>
          </geometry>
          <surface>
            <contact>
              <ode/>
            </contact>
            <friction>
              <ode>
                <mu>0.2</mu>
                <mu2>0.2</mu2>
              </ode>
              <torsional>
                <ode/>
              </torsional>
            </friction>
            <bounce/>
          </surface>
          <max_contacts>10</max_contacts>
        </collision>
        <visual name='Wheel_BR_1_visual'>
          <pose>0.1325 0.115065 0.026 0 -0 0</pose>
          <geometry>
            <mesh>
              <scale>0.001 0.001 0.001</scale>
              <uri>file:///home/godwin/Desktop/BTP/obstacle_avoidance/src/obstacle_avoidance/urdf/meshes/Wheel_BR_1.stl</uri>
            </mesh>
          </geometry>
          <material>
            <script>
              <name>Gazebo/Silver</name>
              <uri>file://media/materials/scripts/gazebo.material</uri>
            </script>
          </material>
        </visual>
        <self_collide>1</self_collide>
        <enable_wind>0</enable_wind>
        <kinematic>0</kinematic>
      </link>
      <joint name='Revolute 11' type='revolute'>
        <pose relative_to='base_link'>-0.1325 0.115065 -0.026 0 -0 0</pose>
        <parent>base_link</parent>
        <child>Wheel_BL_1</child>
        <axis>
          <xyz>0 1 0</xyz>
          <limit>
            <lower>-1e+16</lower>
            <upper>1e+16</upper>
          </limit>
          <dynamics>
            <spring_reference>0</spring_reference>
            <spring_stiffness>0</spring_stiffness>
          </dynamics>
        </axis>
      </joint>
      <link name='Wheel_BL_1'>
        <pose relative_to='Revolute 11'>0 0 0 0 -0 0</pose>
        <inertial>
          <pose>2e-06 0.043 0 0 -0 0</pose>
          <mass>0.34</mass>
          <inertia>
            <ixx>0.001381</ixx>
            <ixy>0</ixy>
            <ixz>0</ixz>
            <iyy>0.001948</iyy>
            <iyz>0</iyz>
            <izz>0.001381</izz>
          </inertia>
        </inertial>
        <collision name='Wheel_BL_1_collision'>
          <pose>0.1325 -0.115065 0.026 0 -0 0</pose>
          <geometry>
            <mesh>
              <scale>0.001 0.001 0.001</scale>
              <uri>file:///home/godwin/Desktop/BTP/obstacle_avoidance/src/obstacle_avoidance/urdf/meshes/Wheel_BL_1.stl</uri>
            </mesh>
          </geometry>
          <surface>
            <contact>
              <ode/>
            </contact>
            <friction>
              <ode>
                <mu>0.2</mu>
                <mu2>0.2</mu2>
              </ode>
              <torsional>
                <ode/>
              </torsional>
            </friction>
            <bounce/>
          </surface>
          <max_contacts>10</max_contacts>
        </collision>
        <visual name='Wheel_BL_1_visual'>
          <pose>0.1325 -0.115065 0.026 0 -0 0</pose>
          <geometry>
            <mesh>
              <scale>0.001 0.001 0.001</scale>
              <uri>file:///home/godwin/Desktop/BTP/obstacle_avoidance/src/obstacle_avoidance/urdf/meshes/Wheel_BL_1.stl</uri>
            </mesh>
          </geometry>
          <material>
            <script>
              <name>Gazebo/Silver</name>
              <uri>file://media/materials/scripts/gazebo.material</uri>
            </script>
          </material>
        </visual>
        <self_collide>1</self_collide>
        <enable_wind>0</enable_wind>
        <kinematic>0</kinematic>
      </link>
      <joint name='Revolute 8' type='revolute'>
        <pose relative_to='base_link'>0.1325 0.115065 -0.026 0 -0 0</pose>
        <parent>base_link</parent>
        <child>Wheel_TL_1</child>
        <axis>
          <xyz>0 1 0</xyz>
          <limit>
            <lower>-1e+16</lower>
            <upper>1e+16</upper>
          </limit>
          <dynamics>
            <spring_reference>0</spring_reference>
            <spring_stiffness>0</spring_stiffness>
          </dynamics>
        </axis>
      </joint>
      <link name='Wheel_TL_1'>
        <pose relative_to='Revolute 8'>0 0 0 0 -0 0</pose>
        <inertial>
          <pose>2e-06 0.043 0 0 -0 0</pose>
          <mass>0.34</mass>
          <inertia>
            <ixx>0.001381</ixx>
            <ixy>0</ixy>
            <ixz>0</ixz>
            <iyy>0.001948</iyy>
            <iyz>0</iyz>
            <izz>0.001381</izz>
          </inertia>
        </inertial>
        <collision name='Wheel_TL_1_collision'>
          <pose>-0.1325 -0.115065 0.026 0 -0 0</pose>
          <geometry>
            <mesh>
              <scale>0.001 0.001 0.001</scale>
              <uri>file:///home/godwin/Desktop/BTP/obstacle_avoidance/src/obstacle_avoidance/urdf/meshes/Wheel_TL_1.stl</uri>
            </mesh>
          </geometry>
          <surface>
            <contact>
              <ode/>
            </contact>
            <friction>
              <ode>
                <mu>0.2</mu>
                <mu2>0.2</mu2>
              </ode>
              <torsional>
                <ode/>
              </torsional>
            </friction>
            <bounce/>
          </surface>
          <max_contacts>10</max_contacts>
        </collision>
        <visual name='Wheel_TL_1_visual'>
          <pose>-0.1325 -0.115065 0.026 0 -0 0</pose>
          <geometry>
            <mesh>
              <scale>0.001 0.001 0.001</scale>
              <uri>file:///home/godwin/Desktop/BTP/obstacle_avoidance/src/obstacle_avoidance/urdf/meshes/Wheel_TL_1.stl</uri>
            </mesh>
          </geometry>
          <material>
            <script>
              <name>Gazebo/Silver</name>
              <uri>file://media/materials/scripts/gazebo.material</uri>
            </script>
          </material>
        </visual>
        <self_collide>1</self_collide>
        <enable_wind>0</enable_wind>
        <kinematic>0</kinematic>
      </link>
      <joint name='Revolute 9' type='revolute'>
        <pose relative_to='base_link'>0.1325 -0.115065 -0.026 0 -0 0</pose>
        <parent>base_link</parent>
        <child>Wheel_TR_1</child>
        <axis>
          <xyz>0 -1 0</xyz>
          <limit>
            <lower>-1e+16</lower>
            <upper>1e+16</upper>
          </limit>
          <dynamics>
            <spring_reference>0</spring_reference>
            <spring_stiffness>0</spring_stiffness>
          </dynamics>
        </axis>
      </joint>
      <link name='Wheel_TR_1'>
        <pose relative_to='Revolute 9'>0 0 0 0 -0 0</pose>
        <inertial>
          <pose>2e-06 -0.043 0 0 -0 0</pose>
          <mass>0.34</mass>
          <inertia>
            <ixx>0.001381</ixx>
            <ixy>0</ixy>
            <ixz>0</ixz>
            <iyy>0.001948</iyy>
            <iyz>0</iyz>
            <izz>0.001381</izz>
          </inertia>
        </inertial>
        <collision name='Wheel_TR_1_collision'>
          <pose>-0.1325 0.115065 0.026 0 -0 0</pose>
          <geometry>
            <mesh>
              <scale>0.001 0.001 0.001</scale>
              <uri>file:///home/godwin/Desktop/BTP/obstacle_avoidance/src/obstacle_avoidance/urdf/meshes/Wheel_TR_1.stl</uri>
            </mesh>
          </geometry>
          <surface>
            <contact>
              <ode/>
            </contact>
            <friction>
              <ode>
                <mu>0.2</mu>
                <mu2>0.2</mu2>
              </ode>
              <torsional>
                <ode/>
              </torsional>
            </friction>
            <bounce/>
          </surface>
          <max_contacts>10</max_contacts>
        </collision>
        <visual name='Wheel_TR_1_visual'>
          <pose>-0.1325 0.115065 0.026 0 -0 0</pose>
          <geometry>
            <mesh>
              <scale>0.001 0.001 0.001</scale>
              <uri>file:///home/godwin/Desktop/BTP/obstacle_avoidance/src/obstacle_avoidance/urdf/meshes/Wheel_TR_1.stl</uri>
            </mesh>
          </geometry>
          <material>
            <script>
              <name>Gazebo/Silver</name>
              <uri>file://media/materials/scripts/gazebo.material</uri>
            </script>
          </material>
        </visual>
        <self_collide>1</self_collide>
        <enable_wind>0</enable_wind>
        <kinematic>0</kinematic>
      </link>
      <plugin name='control' filename='libgazebo_ros_control.so'/>
      <static>0</static>
      <plugin name='gazebo_ros_planar_move' filename='libgazebo_ros_planar_move.so'>
        <ros>
          <namespace>/</namespace>
          <remapping>cmd_vel:=cmd_vel</remapping>
          <remapping>odom:=odom</remapping>
        </ros>
        <update_rate>100</update_rate>
        <publish_rate>10</publish_rate>
        <publish_odom>1</publish_odom>
        <publish_odom_tf>1</publish_odom_tf>
        <odometry_frame>odom_demo</odometry_frame>
        <robot_base_frame>base_link</robot_base_frame>
        <covariance_x>0.0001</covariance_x>
        <covariance_y>0.0001</covariance_y>
        <covariance_yaw>0.01</covariance_yaw>
      </plugin>
      <pose>0 0 0 0 -0 0</pose>
    </model>
  </world>
</sdf>
